File: data.csv
File #,File name,# of Tubes,# walls per CNT,# of Atoms,# of Bonds,Bond Ratio,CNT height,Initial Dia (Ang.),Initial Dia (nm),Cross-sectional area (nm^2),Strain at Break,1/2 Stress (GPa),1/2 Strain,Strength (GPa),Elastic Modulus (GPa)
1,001-2N2M2,2,1,160,236,1.475,24.1694275819999,2.71,0.271,0.665705054092004,0.23600001626340208,27.57371673631904,0.11700001219755157,45.465992445250706,101.57647348318254
6,006-3N2M2,3,1,240,352,1.4666666666666666,24.1694275819999,2.71,0.271,0.998557581138006,0.22600001626340216,21.407266709932603,0.11199999186829908,33.45852757479733,492.5213106179097
11,011-3N5M5,3,1,600,890,1.4833333333333334,25.1579640219999,6.78,0.678,2.637439289319664,0.24099999593414953,47.53048594437231,0.12000000000000005,69.74924622633301,522.2283653797214
16,016-4N3M3,4,1,480,714,1.4875,24.498939729,4.07,0.40700000000000003,1.9458051002612569,0.2450000203292526,54.730767022160364,0.121999991868299,80.4323223531059,473.9277973545803
21,021-4N4M4,4,1,640,936,1.4625,24.8284518759999,5.42,0.542,2.670617649334226,0.231999991868299,27.310469240552777,0.11500002032925262,37.724312893903196,337.2807392975023
26,026-5N2M2,5,1,400,592,1.48,24.1694275819999,2.71,0.271,1.6642626352300098,0.23299998780244854,35.741683013684515,0.11600001626340217,56.14002544610074,104.00454092080211
31,031-5N3M3,5,1,600,882,1.47,24.498939729,4.07,0.40700000000000003,2.432256375326571,0.24600001626340215,35.62665131514637,0.121999991868299,49.36868043189586,323.1405673780862
36,036-5N4M4,5,1,800,1168,1.46,24.8284518759999,5.42,0.542,3.3382720616677823,0.2480000081317011,24.939809622471444,0.12299998780244854,32.613876323595214,340.7848290549011
41,041-6N2M2,6,1,480,716,1.4916666666666667,24.1694275819999,2.71,0.271,1.997115162276012,0.23299998780244854,51.370381696935475,0.11600001626340217,76.9308967070206,454.8690102374307
46,046-6N3M3,6,1,720,1074,1.4916666666666667,24.498939729,4.07,0.40700000000000003,2.918707650391885,0.24700001219755155,60.819347709177116,0.12299998780244854,88.23615876312925,595.488607531437
51,051-6N4M4,6,1,960,1432,1.4916666666666667,24.8284518759999,5.42,0.542,4.005926474001339,0.24900000406585063,60.34290690465627,0.12399998373659794,88.09825314301133,563.5719590304867
56,056-6N5M5,6,1,1200,1790,1.4916666666666667,25.1579640229999,6.78,0.678,5.274878578639328,0.24900000406585063,57.61034242882419,0.12399998373659794,84.75537396355594,528.6000770250788
61,061-7N2M2,7,1,560,836,1.4928571428571429,24.1694275819999,2.71,0.271,2.329967689322014,0.22700001219755156,50.17952871089211,0.11299998780244848,76.5578695811291,521.6660854639694
66,066-7N2M2,7,1,560,816,1.457142857142857,24.1694275819999,2.71,0.271,2.329967689322014,0.24900000406585063,8.48645439121732,0.12399998373659794,13.773313195482013,185.39138785949777
71,071-7N3M3,7,1,840,1230,1.4642857142857142,24.498939729,4.07,0.40700000000000003,3.4051589254571994,0.2450000203292526,30.270606193963733,0.121999991868299,40.30202445636187,344.04703029873366
76,076-7N4M4,7,1,1120,1648,1.4714285714285715,24.8284518759999,5.42,0.542,4.6735808863348955,0.25000000000000006,38.08710329148192,0.12399998373659794,51.868793469459646,407.74294215725155
81,081-7N5M5,7,1,1400,2070,1.4785714285714286,25.1579640229999,6.78,0.678,6.15402500841255,0.25000000000000006,42.397905243022976,0.12399998373659794,60.78004871450981,363.09162987326357
86,086-2N7M7,2,1,560,826,1.475,24.5872322429999,9.49,0.9490000000000001,2.7744048750345454,0.24900000406585063,32.05993560341601,0.12399998373659794,46.89388988789706,262.05604092453916
91,091-3N10M10,3,1,1200,1760,1.4666666666666666,24.3460126089999,13.56,1.356,7.1008539103147115,0.25299998780244853,18.9132775713926,0.1260000162634021,26.99277344058121,173.61739510188252
96,096-4N10M10,4,1,1600,2340,1.4625,24.3460126089999,13.56,1.356,9.467805213752948,0.25499997967074745,14.782020285042853,0.12700001219755164,20.52489667612491,122.89421396547883
101,101-4N7M7,4,1,1120,1652,1.475,24.5872322429999,9.49,0.9490000000000001,5.548809750069091,0.2609999959341495,31.609373353267816,0.13000000000000012,46.07344974748099,158.36812366564618
106,106-4N9M9,4,1,1440,2142,1.4875,25.246256536,12.2,1.22,8.042477193189871,0.25199999186829897,41.396941692883296,0.1250000203292527,60.37758703012213,323.2951760060102
111,111-5N10M10,5,1,2000,2940,1.47,24.3460126089999,13.56,1.356,11.834756517191185,0.24600001626340215,21.737015605986706,0.121999991868299,31.775139695155197,185.5706517505084
116,116-5N6M6,5,1,1200,1752,1.46,24.257720096,8.14,0.8140000000000001,5.598459480366422,0.2550000203292527,17.300041696791567,0.12700001219755164,23.99565969601283,192.59955486372868
121,121-5N8M8,5,1,1600,2384,1.49,24.9167443889999,10.85,1.085,8.42820586618844,0.24700001219755155,46.151760691786166,0.12299998780244854,67.74778973956887,385.49831173931835
126,126-5N9M9,5,1,1800,2664,1.48,25.246256536,12.2,1.22,10.053096491487338,0.25399998373659805,32.823841914751775,0.1260000162634021,48.16455783400366,279.0649156704777
131,131-6N10M10,6,1,2400,3540,1.475,24.3460126089999,13.56,1.356,14.201707820629423,0.25499997967074745,26.9252616681937,0.12700001219755164,38.639401768572355,228.21717968011805
136,136-6N6M6,6,1,1440,2124,1.475,24.257720096,8.14,0.8140000000000001,6.718151376439707,0.25199999186829897,36.177811322994664,0.1250000203292527,51.2735572470669,257.04465316136634
141,141-6N7M7,6,1,1680,2478,1.475,24.5872322429999,9.49,0.9490000000000001,8.323214625103637,0.24299998780244847,31.212199129406347,0.1209999959341496,46.66860765126077,270.13814169411745
146,146-6N8M8,6,1,1920,2832,1.475,24.9167443889999,10.85,1.085,10.113847039426128,0.25900000406585055,31.83614392072911,0.12900000406585058,44.99790324249193,245.4229516973706
151,151-7N10M10,7,1,2800,4140,1.4785714285714286,24.3460126089999,13.56,1.356,16.568659124067658,0.2480000081317011,30.116140747343977,0.12299998780244854,43.69986712507708,227.51095966919323
156,156-7N6M6,7,1,1680,2496,1.4857142857142858,24.257720096,8.14,0.8140000000000001,7.837843272512991,0.2450000203292526,47.16853257523093,0.121999991868299,69.10165639298786,371.957299505601
161,161-7N7M7,7,1,1960,2926,1.4928571428571429,24.5872322429999,9.49,0.9490000000000001,9.710417062620909,0.24700001219755155,51.908474760724395,0.12299998780244854,76.4355849300984,396.2477279881417
166,166-7N7M7,7,1,1960,2856,1.457142857142857,24.5872322429999,9.49,0.9490000000000001,9.710417062620909,0.25399998373659805,12.807881272126778,0.1260000162634021,17.205476295715545,125.23442950469222
171,171-7N8M8,7,1,2240,3280,1.4642857142857142,24.9167443889999,10.85,1.085,11.799488212663816,0.25000000000000006,19.120150581907065,0.12399998373659794,26.900167933503795,203.3473765821807
176,176-7N9M9,7,1,2520,3708,1.4714285714285715,25.246256536,12.2,1.22,14.074335088082275,0.2550000203292527,25.064980036213832,0.12700001219755164,35.61150936977504,230.56481079301537
181,181-2-2-5,2,2,560,830,1.4821428571428572,24.8755250399999,5,0.8,2.1871768054292144,0.21000000000000008,42.337323243685404,0.10399998373659797,63.61715061497081,568.728428734191
186,186-3-2-5,3,2,840,1240,1.4761904761904763,24.8755250399999,5,0.8,3.280765208143822,0.2019999918682991,38.03345319266177,0.10000000000000007,55.89903979769088,505.9996529187066
191,191-4-2-5,4,2,1120,1670,1.4910714285714286,24.8755250399999,5,0.8,4.374353610858429,0.2029999878024485,48.906975410608254,0.10099999593414961,75.13324923894075,576.8252048140238
196,196-4-2-5,4,2,1120,1672,1.4928571428571429,24.8755250399999,5,0.8,4.374353610858429,0.19000000000000009,49.03943049209367,0.09399998373659804,74.17105913086334,629.983406414053
201,201-5-2-5,5,2,1400,2080,1.4857142857142858,24.8755250399999,5,0.8,5.467942013573036,0.20500002032925263,44.803598719034134,0.10199999186829901,67.785362587374,552.1864654183225
206,206-5-2-5,5,2,1400,2092,1.4942857142857142,24.8755250399999,5,0.8,5.467942013573036,0.1829999878024485,47.878083441149045,0.09099999593414955,74.72274064799782,576.1000152781057
211,211,,,,,,,,0,0,,,,,
216,216-6-2-5,6,2,1680,2460,1.4642857142857142,24.8755250399999,5,0.8,6.561530416287644,0.2280000081317011,29.103591648367953,0.11299998780244848,40.598728718854844,445.1892993804285
221,221-6-2-5,6,2,1680,2500,1.4880952380952381,24.8755250399999,5,0.8,6.561530416287644,0.19199999186829902,46.494133984539125,0.09500002032925263,67.60653517772012,588.1102122250534
226,226-2-3-6,2,2,720,1056,1.4666666666666666,24.3381266399999,6,0.9000000000000001,2.57359270182076,0.25800000813170115,41.01388950137589,0.12800000813170104,56.335403220952024,524.8047253118152
231,231-3-3-6,3,2,1080,1584,1.4666666666666666,24.3381266399999,6,0.9000000000000001,3.86038905273114,0.25199999186829897,41.482438432318574,0.1249999796707475,56.8339700740079,526.9948631787944
236,236-4-3-6,4,2,1440,2136,1.4833333333333334,24.3381266399999,6,0.9000000000000001,5.14718540364152,0.22099999593414954,53.67484274216806,0.10999999999999999,79.52010925665091,639.472983172859
241,241-4-3-6,4,2,1440,2142,1.4875,24.3381266399999,6,0.9000000000000001,5.14718540364152,0.20099999593414955,58.5348516632947,0.10000000000000007,82.85904606006187,679.6691354545645
246,246-5-3-6,5,2,1800,2652,1.4733333333333334,24.3381266399999,6,0.9000000000000001,6.433981754551899,0.22000000000000014,45.268615584143326,0.10900000406585059,65.07333323846137,555.0551583153388
251,251-5-3-6,5,2,1800,2676,1.4866666666666666,24.3381266399999,6,0.9000000000000001,6.433981754551899,0.20499997967074743,57.89690730198978,0.10199999186829901,80.75773682101003,683.4617643697575
256,256-6-3-6,6,2,2160,3192,1.4777777777777779,24.3381266399999,6,0.9000000000000001,7.72077810546228,0.21700001219755163,47.886454959218476,0.10800000813170105,70.77762014988011,604.408657812641
261,261-6-3-6,6,2,2160,3222,1.4916666666666667,24.3381266399999,6,0.9000000000000001,7.72077810546228,0.20600001626340217,60.99265416463142,0.10199999186829901,89.43045061385995,681.608742324872
266,266-4-7,1,2,440,652,1.481818181818182,24.6068692379999,7,1,1.4957122623741002,0.19299998780244856,55.716915565197326,0.09600001626340218,76.74159496820224,580.2724293356537
271,271-3-4-7,3,2,1320,1966,1.4893939393939395,24.6068692379999,7,1,4.4871367871223,0.20600001626340217,60.83286347447527,0.10199999186829901,95.00947845017767,742.7297379292487
276,276-3-4-7,3,2,1320,1956,1.481818181818182,24.6068692379999,7,1,4.4871367871223,0.20700001219755157,57.41844794633333,0.10299998780244857,78.26849478747441,646.7547558676953
281,281-4-4-7,4,2,1760,2632,1.4954545454545454,24.6068692379999,7,1,5.982849049496401,0.20499997967074743,67.05538230607002,0.10199999186829901,102.61752419690792,781.598376986746
286,286-5-4-7,5,2,2200,3272,1.4872727272727273,24.6068692379999,7,1,7.478561311870501,0.21900000406585057,62.23232119737755,0.10900000406585059,94.10080820155956,716.5512793479353
291,291-5-4-7,5,2,2200,3284,1.4927272727272727,24.6068692379999,7,1,7.478561311870501,0.2090000040658505,65.80922351629926,0.10399998373659797,98.46600844122709,763.3037988687915
296,296-6-4-7,6,2,2640,3932,1.4893939393939395,24.6068692379999,7,1,8.9742735742446,0.2149999796707475,63.638169600144536,0.10700001219755165,96.65149791761267,712.4493486890242
301,301-6-4-7,6,2,2640,3952,1.496969696969697,24.6068692379999,7,1,8.9742735742446,0.21000000000000008,70.08439057149778,0.10399998373659797,107.17529955377385,755.809435490652
306,306-6-4-7,6,1,2640,3912,1.481818181818182,24.6068692379999,7,1,8.9742735742446,0.21099999593414961,57.58024836834411,0.1049999796707475,77.78532123079354,673.4527981520521
311,311-3N2M2,3,1,240,360,1.5,24.1694275819999,2.71,0.271,0.998557581138006,0.22500002032925262,58.53702763997469,0.11199999186829908,88.66112130611627,593.1612059045312
316,316-4N3M3,4,1,480,720,1.5,24.498939729,4.07,0.40700000000000003,1.9458051002612569,0.2450000203292526,69.58205258213566,0.121999991868299,102.57205043330657,644.951162961436
321,321-5N4M4,5,1,800,1200,1.5,24.8284518759999,5.42,0.542,3.3382720616677823,0.23499997967074748,67.34664010110887,0.11700001219755157,101.50551957593639,655.0473370830741
326,326-6N5M5,6,1,1200,1800,1.5,25.1579640229999,6.78,0.678,5.274878578639328,0.25000000000000006,67.8269805690624,0.12399998373659794,99.55337276548279,635.1652377781397
331,331-8N2M2,8,1,640,960,1.5,24.1694275819999,2.71,0.271,2.662820216368016,0.23000000000000004,59.18626003029521,0.11399998373659803,89.2554902643958,601.6391167927902
336,336-9N3M3,9,1,1080,1620,1.5,24.498939729,4.07,0.40700000000000003,4.3780614755878275,0.24299998780244847,69.64028583846083,0.1209999959341496,102.91095543510922,682.0675683793645
341,341-10N4M4,10,1,1600,2400,1.5,24.8284518759999,5.42,0.542,6.676544123335565,0.2450000203292526,69.22797777130023,0.121999991868299,102.81507077300738,652.3157267945126
346,346-12N5M5,12,1,2400,3600,1.5,25.1579640219999,6.78,0.678,10.549757157278655,0.24299998780244847,66.29390255610056,0.1209999959341496,98.52633325281994,613.2655280538015
351,351-2N6M6,2,1,480,720,1.5,24.257720096,8.14,0.8140000000000001,2.239383792146569,0.25399998373659805,64.75475977203972,0.1260000162634021,94.56588095791419,569.6431152614773
356,356-3N6M6,3,1,720,1080,1.5,24.257720096,8.14,0.8140000000000001,3.3590756882198534,0.2480000081317011,63.56813750410602,0.12299998780244854,93.72536374599375,635.5148384305778
361,361-4N6M6,4,1,960,1440,1.5,24.257720096,8.14,0.8140000000000001,4.478767584293138,0.25399998373659805,64.53934276798603,0.1260000162634021,94.22440279584954,588.7764486671309
366,366-5N6M6,5,1,1200,1800,1.5,24.257720096,8.14,0.8140000000000001,5.598459480366422,0.25199999186829897,64.12638089652998,0.1250000203292527,94.00784834894435,584.4909540728613
371,371-6N6M6,6,1,1440,2160,1.5,24.257720096,8.14,0.8140000000000001,6.718151376439707,0.25199999186829897,64.49466305615569,0.1250000203292527,94.19765411922799,568.9897968354188
376,376-7N6M6,7,1,1680,2520,1.5,24.257720096,8.14,0.8140000000000001,7.837843272512991,0.25000000000000006,64.13117898432762,0.12399998373659794,94.29713334989098,601.2678776672668
381,381-8N6M6,8,1,1920,2880,1.5,24.257720096,8.14,0.8140000000000001,8.957535168586276,0.24299998780244847,62.737772443197116,0.1209999959341496,93.2276381680708,611.5371515730092
386,386-9N6M6,9,1,2160,3240,1.5,24.257720096,8.14,0.8140000000000001,10.07722706465956,0.243999983736598,62.85733647371789,0.1209999959341496,93.34659053714347,599.8044634518507
391,391-10N6M6,10,1,2400,3600,1.5,24.257720096,8.14,0.8140000000000001,11.196918960732845,0.24900000406585063,63.71324551765791,0.12399998373659794,93.73750548276426,608.8470629643011
396,396-12N6M6,12,1,2880,4320,1.5,24.257720096,8.14,0.8140000000000001,13.436302752879413,0.24299998780244847,62.74105068049979,0.1209999959341496,93.08015719867801,612.1361058778243
401,401-N6M6,1,1,240,360,1.5,24.257720096,8.14,0.8140000000000001,1.1196918960732845,0.243999983736598,62.31863301258732,0.1209999959341496,92.90793049798127,604.0979535153779
406,406-2-2-5-8,2,3,1200,1800,1.5,24.9844769489999,8,1.3,4.433415552745917,0.19700001219755164,57.4204323694342,0.09800000813170112,89.6826217307627,634.3783826884405
411,411-2-6-9-12,2,3,2160,3240,1.5,24.916609931,12,1.8000000000000003,7.465052463460068,0.22199999186829908,74.7023286991574,0.10999999999999999,113.9812683938255,760.1061973411112
416,416-2-12-15-18,2,3,3600,5400,1.5,24.721021129,18,2.6,13.9492997004694,0.243999983736598,75.37983191444494,0.1209999959341496,111.67874150181136,708.629507151668
421,421-3-6-9,1,3,720,1080,1.5,24.7921915879999,9,1.4,2.4884555409084745,0.20399998373659803,66.20971862219879,0.10099999593414961,102.77031091813191,763.447631653916
426,426-3-10-13-16,3,3,4680,7020,1.5,24.572197576,16,2.3,16.923131306357494,0.23399998373659794,77.50989332265074,0.11600001626340217,116.96588181053083,786.5594476902692
431,431-4-4-7-10,4,3,3360,5040,1.5,24.4826517959999,10,1.6,12.316299839133425,0.2090000040658505,64.89314888679506,0.10399998373659797,100.33980742282236,714.0078790701764
436,436-4-9-12-15,4,3,5760,8640,1.5,24.916340632,15,2.2,20.9116973393551,0.2309999959341496,76.17368232700994,0.11500002032925262,115.1837384404728,763.5705644766299
441,441-5-3-6-9,5,3,3600,5400,1.5,24.7921915879999,9,1.4,12.442277704542374,0.1990000040658506,64.9699878193378,0.09900000406585052,101.61001717617057,772.5194995697312
446,446-5-8-11,1,3,960,1440,1.5,24.7501185379999,11,1.7000000000000002,3.397946614122721,0.21700001219755163,70.64398950664662,0.10800000813170105,108.17631261466431,759.0711251299921
451,451-5-12-15-18,5,3,9000,13500,1.5,24.721021129,18,2.6,34.8732492511735,0.23900000406585056,74.20819705025248,0.11900000406585051,110.82863606699985,749.9316521568209
456,456-6-6-9-12,6,3,6480,9720,1.5,24.916609931,12,1.8000000000000003,22.395157390380202,0.2150000203292527,73.09684062300028,0.10700001219755165,112.70864247426267,791.951878281097
461,461-6-9-12-15,6,3,8640,12960,1.5,24.916340632,6,2.2,31.36754600903265,0.23500002032925268,77.38831461099562,0.11700001219755157,115.96963124588086,766.46133413784
466,466-7-3-6-9,7,3,5040,7560,1.5,24.7921915879999,7,1.4,17.41918878635932,0.19800000813170104,64.486046853814,0.09800000813170112,101.52076726244485,759.6903085344869
471,471-7-10-13,1,3,1200,1800,1.5,24.2977686829999,7,1.9,4.082813812605295,0.22299998780244848,77.5057147444024,0.11099999593414954,118.41228563531764,817.5340864486773
476,476-8-2-5-8,8,3,4800,7200,1.5,24.9844769489999,8,1.3,17.733662210983667,0.19099999593414949,55.83021412209652,0.09499997967074744,88.04902988588947,692.3307496314231
481,481-8-8-11-14,8,3,10560,15840,1.5,24.6316666409999,8,2.0999999999999996,38.644102913277315,0.22600001626340216,73.67427164773052,0.11199999186829908,112.3954236590992,781.1998101371606
486,486-8-12-15-18,8,3,14400,21600,1.5,24.721021129,8,2.6,55.7971988018776,0.2309999959341496,72.26734664583627,0.11500002032925262,109.5278046929462,718.5658778377551
491,491-9-7-10-13,9,3,10800,16200,1.5,24.2977686829999,9,1.9,36.745324313447654,0.21199999186829901,74.27900066489106,0.1049999796707475,115.99973724045363,815.8752356776446
496,496-9-12-15,1,3,1440,2160,1.5,24.916340632,9,2.2,5.227924334838775,0.23900000406585056,79.04475932421809,0.11900000406585051,117.05925653833596,732.9474160237133
501,501-10-6-9-12,10,3,10800,16200,1.5,24.916609931,10,1.7999999999999998,37.32526231730033,0.21399998373659795,72.63953943993246,0.1060000162634021,112.66268581516987,794.8891986352711
506,506-10-12-15-18,10,3,18000,27000,1.5,24.721021129,10,2.6,69.746498502347,0.24099999593414953,74.70237954129249,0.12000000000000005,111.13512116456646,732.8488004039133
511,511-12-4-7-10,12,3,10080,15120,1.5,24.4826517959999,12,1.6,36.94889951740028,0.1960000162634021,61.35951291342854,0.09700001219755158,97.47939588229043,718.0697671334735
516,516-12-10-13-16,12,3,18720,28080,1.5,24.572197576,12,2.3,67.69252522542997,0.22299998780244848,74.97819567577424,0.11099999593414954,115.15786084410159,776.4032696897684
521,521-D2-3-6,2,2,720,1080,1.5,24.3381266399999,2,0.8999999999999999,2.5735927018207576,0.20700001219755157,66.18158411571193,0.10299998780244857,102.41857561514303,703.8486954701985
526,526-D2-8-11,2,2,1520,2280,1.5,24.7770909179999,2,1.7,6.795893228245442,0.23900000406585056,63.951343207834284,0.11900000406585051,95.18050526420998,605.8692668192416
531,531-D3-4-7,3,2,1320,1980,1.5,24.6068692379999,3,1,4.4871367871223,0.21199999186829901,73.06243854647462,0.1049999796707475,112.75712201682195,838.3395127680202
536,536-D3-10-13,3,2,2760,4140,1.5,24.209671078,3,1.9,12.248441437815885,0.24600001626340215,66.29369324946647,0.121999991868299,97.95120850868437,637.5208469846522
541,541-D4-5-8,4,2,2080,3120,1.5,25.0095211709999,4,1.3,8.866831105491833,0.22700001219755156,62.165854606144826,0.11299998780244848,93.97073767869779,606.628824856145
546,546-D4-11-14,4,2,4000,6000,1.5,24.540441762,4,2.0999999999999996,19.322051456638658,0.24900000406585063,61.572783476196776,0.12399998373659794,90.54373792845108,587.2547737519469
551,551-D5-6-9,5,2,3000,4500,1.5,24.85084196,5,1.4,12.442277704542374,0.23800000813170116,66.97984495820377,0.11800000813170111,99.6448456694854,688.0687779578051
556,556-D6-2-5,6,2,1680,2520,1.5,24.8755250399999,6,0.8,6.561530416287644,0.20500002032925263,56.46222781193503,0.10199999186829901,86.93990165883471,644.6441203856893
561,561-D6-8-11,6,2,4560,6840,1.5,24.7770909179999,6,1.7000000000000002,20.387679684736327,0.243999983736598,64.55321808275113,0.1209999959341496,95.7004146141729,625.6178528853378
566,566-D7-3-6,7,2,2520,3780,1.5,24.3381266399999,7,0.8999999999999999,9.007574456372652,0.21700001219755163,68.8622510336127,0.10800000813170105,104.82952457666468,749.1662937991265
571,571,,,,,,,,0,0,,,,,
576,576,,,,,,,,0,0,,,,,
581,581,,,,,,,,0,0,,,,,
586,586,,,,,,,,0,0,,,,,
591,591-D8-2-5,8,2,2240,3360,1.5,24.8755250399999,5,0.8,8.748707221716858,0.2019999918682991,55.795364324960865,0.10000000000000007,86.74044565700092,645.8001151406656
596,596-D8-8-11,8,2,6080,9120,1.5,24.7770909179999,11,1.7000000000000002,27.183572912981766,0.2400000000000001,63.698367929375145,0.11900000406585051,95.16013380524119,639.1859372789936
601,601-D9-3-6,9,2,3240,4860,1.5,24.3381266399999,6,0.9,11.581167158193413,0.21299998780244855,67.82533128403112,0.1060000162634021,104.12341612500698,737.2914699300858
606,606-D9-10-13,9,2,8280,12420,1.5,24.209671078,13,1.9,36.745324313447654,0.23800000813170116,64.4573015020576,0.11800000813170111,96.96975535906788,648.8532306059078
611,611-D10-5-8,10,2,5200,7800,1.5,25.0095211709999,8,1.3,22.167077763729583,0.2160000162634021,59.554784802910945,0.10700001219755165,92.24612292882482,639.9904481362456
616,616-D10-13,1,2,920,1380,1.5,24.209671078,13,1.9,4.082813812605295,0.24900000406585063,66.95397581068225,0.12399998373659794,98.49615599644254,632.4130829626649
621,621-D12-5-8,12,2,6240,9360,1.5,25.0095211709999,8,1.3,26.6004933164755,0.22399998373659802,61.15500154532933,0.11099999593414954,93.36761915349248,621.2964649559462
626,626-2N9M9,2,1,720,1080,1.5,24.595121,12.2,1.22,4.0212385965949355,0.25499997967074745,53.97329523214384,0.12700001219755164,79.05178089757996,446.35224905520715
631,631-8N11M11,8,1,3520,5280,1.5,24.595121,14.92,1.492,22.018694059515223,0.25099999593414957,48.132263104155534,0.1249999796707475,70.6390665605823,398.96143189602833
636,636-DDWCNT8-11,1,2,758,1134,1.4960422163588392,24.595121,14.92,1.492,2.752336757439403,0.15500002032925259,54.89508495132898,0.07700001219755159,94.19192282808262,667.8761079544576
641,641-DN9M9,1,1,359,537,1.4958217270194987,24.595121,12.2,1.22,2.0106192982974678,0.1670000121975516,37.539939784650876,0.08299998780244858,63.55233209141647,436.3744300011202
646,646-DTWCNT6-9-12,1,3,1077,1611,1.4958217270194987,24.595121,16.27,1.627,3.1636222866749284,0.1380000081317011,59.41852942046368,0.06800000813170108,102.9345076987162,793.753088311034
651,651-DWCNT9-12,1,2,838,1254,1.496420047732697,24.595121,16.27,1.627,3.1636222866749284,0.1670000121975516,56.73807616833964,0.08299998780244858,94.72064962868008,642.9467000890544
656,656-N10M10,1,1,400,600,1.5,24.595121,13.56,1.356,2.366951303438237,0.2570000121975516,51.5851892114949,0.12800000813170104,75.00266758423417,421.5817328902973
661,661-3D2N13M13,3,1,1554,2322,1.494208494208494,24.595121,17.63,1.763,10.820703030289343,0.16099999593414957,30.17941383064778,0.08000000000000008,51.02036735138065,357.77144114632296
666,666-6D3N14M14,6,1,3342,4986,1.4919210053859964,24.595121,18.98,1.8980000000000001,24.453924737686584,0.15600001626340212,27.69374884779661,0.07700001219755159,46.68297166897843,337.4832189285006
671,671-D2N14M14,1,1,558,834,1.4946236559139785,24.595121,18.98,1.8980000000000001,4.075654122947764,0.16399998373659808,29.18572647420377,0.08099999593414949,49.28592610776555,341.3363352580801
676,676-D4N13M13,1,1,516,768,1.4883720930232558,24.595121,17.63,1.763,3.6069010100964474,0.1629999878024485,29.797513291503655,0.08099999593414949,49.6282363980959,348.1055261475282
681,681-DWCNT13-D416,1,2,1156,1728,1.494809688581315,24.595121,21.7,2.17,5.107051557491907,0.1629999878024485,48.69580216633822,0.08099999593414949,80.34151962983611,562.5223578020741
686,686-N19M19,1,1,760,1140,1.5,24.595121,25.76,2.5760000000000005,6.862758886284448,0.2560000162634021,34.66744905386435,0.12700001219755164,49.998095503649246,281.7884859228624
691,691-D4DWCNT12-15,1,2,1072,1596,1.4888059701492538,24.595121,20.34,2.0340000000000003,4.576826115789637,0.15500002032925259,42.72833939623698,0.07700001219755159,77.3871016205749,557.2376398284792
696,696-4D4DWCNT12-15,4,2,4288,6384,1.4888059701492538,24.595121,20.34,2.0340000000000003,18.307304463158548,0.1509999959341495,41.91641111322466,0.07499997967074745,76.3491958586154,558.6107167896569
701,701-D4DWCNT11-14,1,2,992,1476,1.4879032258064515,24.595121,18.98,1.8980000000000001,4.075654122947764,0.16000000000000003,45.81238879703995,0.07900000406585055,81.93653145614765,578.5720517065547
706,706-4D4DWCNT11-14,4,2,3968,5904,1.4879032258064515,24.595121,18.98,1.8980000000000001,16.302616491791056,0.15700001219755153,44.87823608821384,0.07800000813170115,80.86118257881208,578.3780727565223
711,711-D4DWCNT13-16,1,2,1152,1716,1.4895833333333333,24.595121,21.7,2.17,5.107051557491907,0.16000000000000003,42.399668313423184,0.07900000406585055,76.88199730091964,540.8299868479705
716,716-4D4DWCNT13-16,4,2,4608,6864,1.4895833333333333,24.595121,21.7,2.17,20.42820622996763,0.1580000081317011,41.74804637271439,0.07800000813170115,76.2736163825935,540.6188962159634
721,721-D4DWCNT14-17,1,2,1232,1836,1.4902597402597402,24.595121,23.05,2.305,5.662112074518969,0.15600001626340212,39.823208367492086,0.07700001219755159,72.59523716765594,522.7617060506966
726,726-3D4DWCNT14-17,3,2,3696,5508,1.4902597402597402,24.595121,23.05,2.305,16.986336223556908,0.15600001626340212,39.87422003252838,0.07700001219755159,73.02417131605735,523.1950931240211
731,731-D4DWCNT15-18,1,2,1312,1956,1.4908536585365855,24.595121,24.41,2.4410000000000003,6.250230785641593,0.16000000000000003,39.6018255488828,0.07900000406585055,71.45210721282785,505.21123769882524
736,736-5D4DWCNT15-18,5,2,6560,9780,1.4908536585365855,24.595121,24.41,2.4410000000000003,31.251153928207962,0.1580000081317011,39.119085011510585,0.07800000813170115,70.99807280787286,505.90667932563207
741,741-D4TWCNT11-14-17,1,3,1668,2484,1.4892086330935252,24.595121,23.05,2.305,5.662112074518969,0.15500002032925259,69.52051779461391,0.07700001219755159,119.0999,864.2289
746,746-D8TWCNT11-14-17,1,3,1656,2448,1.4782608695652173,24.595121,23.05,2.305,5.662112074518969,0.14600001626340206,10.591036293112541,0.07199999186829897,18.31748,137.9316
751,751-D4TWCNT12-15-18,1,3,1788,2664,1.4899328859060403,24.595121,24.41,2.4410000000000003,6.250230785641593,0.15299998780244844,54.547256733838786,0.07600001626340205,92.93733,682.2724
756,756-4D4TWCNT12-15-18,4,3,7152,10656,1.4899328859060403,24.595121,24.41,2.4410000000000003,25.00092314256637,0.153999983736598,54.4979925890525,0.07600001626340205,94.21559,682.6361
761,761-D4TWCNT13-16-19,1,3,1908,2844,1.490566037735849,24.595121,25.76,2.5760000000000005,6.862758886284448,0.1580000081317011,54.90262518821973,0.07800000813170115,93.74523,665.9351
766,766-4D4TWCNT13-16-19,4,3,7632,11376,1.490566037735849,24.595121,25.76,2.5760000000000005,27.451035545137792,0.1580000081317011,54.739770809122795,0.07800000813170115,93.25668,666.7378
771,771-D4TWCNT14-17-20,1,3,2028,3024,1.4911242603550297,24.595121,27.12,2.712,7.508770866827422,0.16000000000000003,53.68377896664013,0.07900000406585055,91.89031,647.5971
776,776-2D4TWCNT14-17-20,2,3,4056,6048,1.4911242603550297,24.595121,27.12,2.712,15.017541733654843,0.16000000000000003,53.9005385904684,0.07900000406585055,92.14454,650.9291
781,781-D4TWCNT15-18-21,1,3,2148,3204,1.4916201117318435,24.595121,29.83,2.983,8.882671801049394,0.16099999593414957,48.79800618333625,0.08000000000000008,82.6368,583.4254
786,786-3D4TWCNT15-18-21,3,3,6444,9612,1.4916201117318435,24.595121,29.83,2.983,26.648015403148182,0.16000000000000003,48.38871920396377,0.07900000406585055,81.88442,583.2199
791,791-DN11M11,1,1,438,654,1.4931506849315068,24.595121,14.92,1.492,2.752336757439403,0.15900000406585063,31.959489038964403,0.07900000406585055,54.87007,386.668
796,796-6DN11M11,6,1,2635,3945,1.4971537001897532,24.595121,14.92,1.492,16.514020544636416,0.1629999878024485,33.50041647292296,0.08099999593414949,56.69459,393.9166
801,801-11DN11M11,11,1,4827,7207,1.4930598715558319,24.595121,14.92,1.492,30.27570433183343,0.15700001219755153,31.732959595153968,0.07800000813170115,53.9328,387.0578
806,806-4DN12M12,4,1,1914,2856,1.4921630094043887,24.595121,16.27,1.627,12.654489146699714,0.13399998373659802,25.834957867374012,0.06600001626340213,45.70381,364.4714
811,811-9DN12M12,9,1,4308,6432,1.4930362116991645,24.595121,16.27,1.627,28.472600580074356,0.14099999593414958,27.355158116184978,0.07000000000000002,47.71275,366.553
816,816-2DN13M13,2,1,1034,1540,1.4893617021276595,24.595121,17.63,1.763,7.213802020192895,0.14600001626340206,26.44706831203585,0.07199999186829897,44.92282,342.9021
821,821-7DN13M13,7,1,3633,5434,1.4957335535370218,24.595121,17.63,1.763,25.248307070675132,0.16499997967074748,30.31361130769641,0.08199999186829904,44.69788,352.924
826,826-12DN13M13,12,1,6213,9260,1.4904233059713503,24.595121,17.63,1.763,43.28281212115737,0.13700001219755156,24.979374735739746,0.06800000813170108,42.47587,343.8376
831,831-5DN14M14,5,1,2789,4154,1.4894227321620652,24.595121,18.98,1.8980000000000001,20.37827061473882,0.13099999593414952,22.677024872600274,0.06500002032925259,40.25317,325.5663
836,836-10DN14M14,10,1,5586,8337,1.4924812030075187,24.595121,18.98,1.8980000000000001,40.75654122947764,0.13600001626340216,23.89579938416054,0.06700001219755168,41.11306,331.0653
841,841-3DN15M15,3,1,1793,2672,1.4902398215281651,24.595121,20.34,2.0340000000000003,13.730478347368912,0.13399998373659802,22.050101782918645,0.06600001626340213,38.55725,311.8715
846,846-8DN15M15,8,1,4791,7151,1.4925902734293466,24.595121,20.34,2.0340000000000003,36.614608926317096,0.14600001626340206,24.09660411192517,0.07199999186829897,42.30511,315.3564
851,851-N6M6,1,1,240,360,1.5,24.595121,8.14,0.8140000000000001,1.1196918960732845,0.25299998780244853,63.49206772964273,0.1260000162634021,92.91638822061125,530.4524003454153
856,856-2N6M6,2,1,480,720,1.5,24.595121,8.14,0.8140000000000001,2.239383792146569,0.2560000162634021,63.74881313979426,0.12700001219755164,93.75686301749678,530.165300580619
861,861-N7M7,1,1,280,420,1.5,24.595121,9.49,0.9490000000000001,1.3872024375172727,0.25199999186829897,49.01437838617715,0.1249999796707475,72.49542292232071,411.5964619085199
866,866-2N7M7,2,1,560,840,1.5,24.595121,9.49,0.9490000000000001,2.7744048750345454,0.25499997967074745,50.048277260594105,0.12700001219755164,72.95695445408695,412.72136609523074
871,871-N8M8,1,1,320,480,1.5,24.595121,10.85,1.085,1.685641173237688,0.25800000813170115,56.854387900271924,0.12800000813170104,83.16551561801634,471.6126309024484
876,876-2N8M8,2,1,640,960,1.5,24.595121,10.85,1.085,3.371282346475376,0.25199999186829897,55.60572111697698,0.1249999796707475,82.41526306775434,472.8054376728104
881,881-N9M9,1,1,360,540,1.5,24.595121,11.53,1.153,1.8457555844205455,0.25800000813170115,59.03694766535704,0.12800000813170104,85.698619214986,486.40644423549156
886,886-2N9M9,2,1,720,1080,1.5,24.595121,11.53,1.153,3.691511168841091,0.25299998780244853,57.73138416218532,0.1260000162634021,85.28362171331585,483.9288923878958
891,891-N10M10,1,1,400,600,1.5,24.595121,13.56,1.356,2.366951303438237,0.25499997967074745,50.439596742885364,0.12700001219755164,74.22736201442811,421.3556468708911
896,896-2N10M10,2,1,800,1200,1.5,24.595121,13.56,1.356,4.733902606876474,0.25900000406585055,51.4750632431848,0.12900000406585058,74.61811197886426,420.2275068633765
901,901-2N10M10_DC1,2,1,799,1197,1.4981226533166458,24.595121,13.56,1.356,4.733902606876474,0.16000000000000003,33.67343080548889,0.07900000406585055,58.62849451605219,416.0859259701197
906,906-2N10M10_DC2,2,1,798,1195,1.4974937343358397,24.595121,13.56,1.356,4.733902606876474,0.17299998780244857,36.47838095748403,0.08600001626340212,61.49904554330777,414.28799839044586
911,911-2N6M6_DC1,2,1,479,717,1.4968684759916493,24.595121,8.14,0.8140000000000001,2.239383792146569,0.16000000000000003,42.31260781191149,0.07900000406585055,73.56077944849724,522.1106517048378
916,916-2N6M6_DC2,2,1,478,715,1.49581589958159,24.595121,8.14,0.8140000000000001,2.239383792146569,0.1709999959341495,44.7534801407885,0.08499997967074753,76.31387705368674,519.245071128374
921,921-2N7M7_DC1,2,1,559,837,1.4973166368515205,24.595121,9.49,0.9490000000000001,2.7744048750345454,0.16199999186829897,40.584105637336236,0.08000000000000008,70.07492643243538,495.95223882295437
926,926-2N7M7_DC2,2,1,558,835,1.496415770609319,24.595121,9.49,0.9490000000000001,2.7744048750345454,0.1380000081317011,35.45553321192422,0.06800000813170108,62.83327373017927,489.0031862318136
931,931-2N8M8_DC1,2,1,639,957,1.4976525821596245,24.595121,10.85,1.085,3.371282346475376,0.16499997967074748,38.90119712255637,0.08199999186829904,66.71838755921212,465.5271663601048
936,936-2N8M8_DC2,2,1,638,955,1.4968652037617556,24.595121,10.85,1.085,3.371282346475376,0.14000000000000004,33.16830641980935,0.06900000406585062,59.07950159386556,460.67525276424834
941,941-2N9M9_DC1,2,1,719,1077,1.497913769123783,24.595121,12.2,1.22,4.0212385965949355,0.16500002032925265,36.88149258075656,0.08199999186829904,63.11585676195445,440.52046658483494
946,946-2N9M9_DC2,2,1,718,1075,1.4972144846796658,24.595121,12.2,1.22,4.0212385965949355,0.14199999186829898,32.06927222411167,0.07000000000000002,56.50923050850936,435.5221723495635
951,951-2TWCNT11-14-17_D4_5,2,3,3333,4959,1.4878487848784878,24.595121,23.05,2.305,11.324224149037939,0.14600001626340206,51.60676645939129,0.07199999186829897,91.14819457396369,693.380499044619
956,956-3TWCNT11-14-17_D8_4_5,3,3,4989,7407,1.4846662657847265,24.595121,23.05,2.305,16.986336223556908,0.14800000813170117,52.05739463854092,0.07299998780244851,90.65056692068903,684.82887181476
961,961-2TWCNT12-15-18_D4_5,2,3,3573,5319,1.4886649874055415,24.595121,24.41,2.4410000000000003,12.500461571283186,0.13700001219755156,47.91291471641221,0.06800000813170108,85.25027974387365,676.8345498210465
966,966-3D4TWCNT12-15-18,3,3,5364,7992,1.4899328859060403,24.595121,24.41,2.4410000000000003,18.75069235692478,0.15500002032925259,53.93087007232665,0.07700001219755159,93.11771043658548,680.6395723630317
971,971-2TWCNT13-16-19_D4_5,2,3,3813,5679,1.4893784421715184,24.595121,25.76,2.5760000000000005,13.725517772568896,0.15900000406585063,54.068316608856,0.07900000406585055,92.76262011427167,662.8810560768404
976,976-3D4TWCNT13-16-19,3,3,5724,8532,1.490566037735849,24.595121,25.76,2.5760000000000005,20.588276658853346,0.16000000000000003,54.06516495262104,0.07900000406585055,92.89202654818936,665.0310645269606
981,981-2TWCNT14-17-20_D4_5,2,3,4053,6039,1.4900074019245004,24.595121,27.12,2.712,15.017541733654843,0.1580000081317011,51.73985088967876,0.07800000813170115,89.3692087736866,644.962229185935
986,986-3D4TWCNT14-17-20,3,3,6084,9072,1.4911242603550297,24.595121,27.12,2.712,22.526312600482264,0.16000000000000003,52.3863450093417,0.07900000406585055,90.5631501166329,646.6521651373225
991,991-2TWCNT15-18-21_D4_5,2,3,4293,6399,1.490566037735849,24.595121,29.83,2.983,17.76534360209879,0.15500002032925259,46.06916358623732,0.07700001219755159,79.68926014688311,579.9759622136216
996,996-2D4TWCNT15-18-21,2,3,4296,6408,1.4916201117318435,24.595121,29.83,2.983,17.76534360209879,0.1580000081317011,46.7144591043713,0.07800000813170115,80.38043764963084,581.4539206169344
1001,1001-2DWCNT11-14_D4_5,2,2,1982,2946,1.486377396569122,24.595121,18.98,1.8980000000000001,8.151308245895528,0.14700001219755163,42.82785596134071,0.07299998780244851,74.9796938976536,570.5343404632755
1006,1006-3D4DWCNT11-14,3,2,2976,4428,1.4879032258064515,24.595121,18.98,1.8980000000000001,12.226962368843292,0.15700001219755153,46.21450694453868,0.07800000813170115,79.73707050702727,576.7316556239404
1011,1011-2DWCNT12-15_D4_5,2,2,2142,3186,1.4873949579831933,24.595121,20.34,2.0340000000000003,9.153652231579274,0.1500000000000001,42.34830862240585,0.07399998373659805,74.62413256874198,552.8327367057444
1016,1016-3D4DWCNT12-15,3,2,3216,4788,1.4888059701492538,24.595121,20.34,2.0340000000000003,13.730478347368912,0.1509999959341495,43.07028993504643,0.07499997967074745,75.41608377373896,556.4648486763493
1021,1021-2DWCNT13-16_D4_5,2,2,2302,3426,1.4882710686359688,24.595121,21.7,2.17,10.214103114983814,0.15600001626340212,42.804655427064986,0.07700001219755159,73.95845120591198,536.7995206454566
1026,1026-3D4DWCNT13-16,3,2,3456,5148,1.4895833333333333,24.595121,21.7,2.17,15.321154672475721,0.15700001219755153,42.93890952219946,0.07800000813170115,74.38860905498879,538.4077443030036
1031,1031-2DWCNT14-17_D4_5,2,2,2462,3666,1.4890333062550771,24.595121,23.05,2.305,11.324224149037939,0.16099999593414957,42.26998399787108,0.08000000000000008,72.86471663082747,517.8650088189622
1036,1036-2D4DWCNT14-17,2,2,2464,3672,1.4902597402597402,24.595121,23.05,2.305,11.324224149037939,0.15700001219755153,41.66034309758051,0.07800000813170115,71.82446543776604,521.1418369359106
1041,1041-2DWCNT15-18_D4_5,2,2,2622,3906,1.4897025171624714,24.595121,24.41,2.4410000000000003,12.500461571283186,0.15500002032925259,39.69298951215688,0.07700001219755159,68.98270304094227,501.54357286662975
1046,1046-3D4DWCNT15-18,3,2,3936,5868,1.4908536585365855,24.595121,24.41,2.4410000000000003,18.75069235692478,0.15700001219755153,40.56702791262456,0.07800000813170115,69.56496073396325,504.14561860012583
1051,1051-8DWCNT_12nm,8,2,54080,81120,1.5,24.595121,120,12,962.9886261936952,0.22900000406585064,16.972277742199836,16.972277742199836,24.61100689181099,155.31726387039402
1056,1056-N6M6_1SW_dia,1,1,240,360,1.5,24.595121,8.14,0.8140000000000001,1.1196918960732845,0.1629999878024485,48.587554275784186,0.08099999593414949,78.76651561573986,609.6080862103108
1061,1061-N8M8_1SW,1,1,320,480,1.5,24.595121,10.85,1.085,1.685641173237688,0.1670000121975516,44.608225989529004,0.08299998780244858,72.50106652309853,625.1619908927387
1066,1066-N10M10_2SW,1,1,400,600,1.5,24.595121,13.56,1.356,2.366951303438237,0.16099999593414957,37.125215488280325,0.08000000000000008,61.196465715902264,478.67222954811064
1071,1071-N13M13_1SW,1,1,520,780,1.5,24.595121,17.63,1.763,3.6069010100964474,0.16199999186829897,32.48476401876157,0.08000000000000008,53.68917357119108,443.69133045181127
1076,1076-N15M15_2SW,1,1,600,900,1.5,24.595121,20.34,2.0340000000000003,4.576826115789637,0.16000000000000003,28.982093374091708,0.07900000406585055,48.023998333375424,387.69195290659434
1081,1081-N18M18_1SW,1,1,720,1080,1.5,24.595121,24.41,2.4410000000000003,6.250230785641593,0.1629999878024485,26.386689241811283,0.08099999593414949,43.42612373703627,343.4079683711444
1086,1086-N20M20_2SW,1,1,800,1200,1.5,24.595121,27.12,2.712,7.508770866827422,0.16399998373659808,24.08276283566567,0.08099999593414949,39.52518065882934,319.4930298667603
1091,1091-N21M21_2SW_mixed,1,1,840,1260,1.5,24.595121,29.83,2.983,8.882671801049394,0.16600001626340205,23.349004411103223,0.08199999186829904,38.573931068223274,298.21856157351124
1096,1096-2N7M7_1SW,2,1,560,840,1.5,22.873443,9.49,0.9490000000000001,2.7744048750345454,0.24599999999999994,37.948483251227394,0.12299999999999989,85.29614759265715,446.7026530326151
1101,1101-2N9M9_2SW,2,1,720,1080,1.5,22.873443,12.2,1.22,4.0212385965949355,0.23699999999999988,29.89884890595863,0.1189999999999999,71.7658587732627,317.57402644819047
1106,1106-2N12M12_1SW,2,1,960,1440,1.5,22.873443,16.27,1.627,6.327244573349857,0.24399999999999994,26.233260528866843,0.12199999999999997,61.45014683193356,332.3965258751809
1111,1111-2N14M14_2SW,2,1,1120,1680,1.5,22.873443,18.98,1.8980000000000001,8.151308245895528,0.22499999999999992,18.413885810658353,0.11299999999999992,50.51734095836317,310.1600730910182
1116,1116-2N17M17_1SW,2,1,1360,2040,1.5,22.873443,23.05,2.305,11.324224149037939,0.2539999999999999,19.888856824210873,0.1269999999999999,48.219055822248016,267.52445457887353
1121,1121-2N19M19_2SW,2,1,1520,2280,1.5,22.873443,25.76,2.576,13.72551777256889,0.24299999999999986,16.97997215169113,0.12199999999999997,42.98084172544796,260.3033876553174
1126,1126-2N21M21_2SW_dia,2,1,1680,2520,1.5,22.873443,29.83,2.9829999999999997,17.76534360209879,0.24399999999999994,14.72168048448912,0.12199999999999997,36.81300308555853,216.71566296148728
1131,1131-4N6M6_2SW_hor,4,1,960,1440,1.5,22.873443,8.139999999999999,0.814,4.478767584293138,0.24999999999999992,32.38494320981623,0.12499999999999989,82.2104810601926,491.1756051144155
1136,1136-4N9M9_1SW,4,1,1440,2160,1.5,22.873443,12.2,1.22,8.042477193189871,0.23999999999999996,26.706365107504492,0.11999999999999998,69.12637672457227,405.42367918461315
1141,1141-4N11M11_2SW,4,1,1760,2640,1.5,22.873443,14.92,1.492,11.009347029757611,0.24099999999999988,23.824022103762953,0.1209999999999999,60.871211607698335,354.5925608879079
1146,1146-4N14M14_1SW,4,1,2240,3360,1.5,22.873443,18.98,1.8980000000000001,16.302616491791056,0.24399999999999994,20.108494223750245,0.12199999999999997,52.444543304811276,308.1786272777814
1151,1151-4N16M16_2SW,4,1,2560,3840,1.5,22.873443,21.7,2.17,20.42820622996763,0.24399999999999994,18.150240663974387,0.12199999999999997,47.472974541517914,279.5399842979545
1156,1156-4N19M19_1SW,4,1,3040,4560,1.5,22.873443,25.76,2.576,27.45103554513778,0.24499999999999986,16.433774768849773,0.12299999999999989,42.71537032115102,258.22059183543456
1161,1161-4N21M21_1SW_mixed,4,1,3360,5040,1.5,22.873443,29.83,2.9829999999999997,35.53068720419758,0.24599999999999994,13.824443062556908,0.12299999999999989,36.105327037489204,213.82412813420126
1166,1166-18DWCNT12_15_SW,18,2,19440,29160,1.5,22.873443,20.339999999999996,2.034,82.38287008421344,0.24375624375624372,47.00195827483173,0.12087912087912094,102.85011975167005,701.000166803172
1171,1171-32DWCNT12_15_frac,32,2,34320,50856,1.481818181818182,22.873443,20.339999999999996,2.034,146.45843570526833,0.3146853146853147,46.30164300011659,0.1568431568431568,78.27834769371707,455.00154696710297
1176,1176-72N15M15,72,1,43200,63720,1.475,22.873443,20.339999999999996,2.034,329.53148033685375,0.32067932067932065,16.712945343945876,0.15984015984015987,30.570323232778097,184.10541834972693
1181,1181-60_degree_junc,1,1,9590,14374,1.4988529718456727,468.8,10.96,1.096,1.7110495892217594,0.09,34.148350712307035,0.04950000000000001,60.30615631396767,729.9161907952627
1182,1182-90_degree_junc,1,1,9138,13700,1.4992339680455242,468.8,10.96,1.096,1.7110495892217594,0.08860000000000003,30.599198909207093,0.04419999999999998,55.37093343087785,728.5505455250502